Workbook

Sheet Dashboard
J22: =D31 -> 0 | K22: 0.07 | L22: 0.075 | M22: 0.08 | N22: 0.085 | O22: 0.095
J23: 0.025 | K23: 202.40102 | L23: 181.26706 | M23: 164.00201 | N23: 149.63802 | O23: 127.1245
J24: 0.035 | K24: 251.48027 | L24: 219.02646 | M24: 193.81485 | N24: 173.67209 | O24: 143.52199
J25: 0.04 | K25: 288.28971 | L25: 245.99745 | M25: 214.31118 | N25: 189.69481 | O25: 153.95676
J26: 0.05 | K26: 417.12274 | L26: 332.30464 | M26: 275.80017 | N26: 235.474 | O26: 181.78281
J27: 0.06 | K27: 803.62183 | L27: 533.68809 | M27: 398.77814 | N27: 317.87654 | O27: 225.50946
B39: ='Profit and loss statement'!E2 -> FY 2026 (E) | C39: ='Profit and loss statement'!F2 -> FY 2027 E | D39: ='Profit and loss statement'!G2 -> FY 2028 E | E39: ='Profit and loss statement'!H2 -> FY 2029 E | F39: ='Profit and loss statement'!I2 -> FY 2030 E | G39: ='Profit and loss statement'!J2 -> FY 2031 E
A40: Revenue | B40: ='Profit and loss statement'!E3 -> 4420 | C40: ='Profit and loss statement'!F3 -> 5569.2 | D40: ='Profit and loss statement'!G3 -> 6905.808 | E40: ='Profit and loss statement'!H3 -> 8425.0858 | F40: ='Profit and loss statement'!I3 -> 10025.852 | G40: ='Profit and loss statement'!J3 -> 11629.988
A41: %Revenue Growth | B41: ='Revenue Model'!E5 -> 0.27671866 | C41: ='Revenue Model'!F5 -> 0.26 | D41: ='Revenue Model'!G5 -> 0.24 | E41: ='Revenue Model'!H5 -> 0.22 | F41: ='Revenue Model'!I5 -> 0.19 | G41: ='Revenue Model'!J5 -> 0.16
A42: fcf | B42: =DCF!B16 -> 991.76877 | C42: =DCF!C16 -> 1483.2679 | D42: =DCF!D16 -> 2197.189 | E42: =DCF!E16 -> 2737.8464 | F42: =DCF!F16 -> 3178.5216 | G42: =DCF!G16 -> 3631.9693
A43: FCF MARGIN | B43: =B42/B40 -> 0.22438207 | C43: =C42/C40 -> 0.2663341 | D43: =D42/D40 -> 0.31816538 | E43: =E42/E40 -> 0.32496362 | F43: =F42/F40 -> 0.31703256 | G43: =G42/G40 -> 0.31229346
A44: Rule of 40 | B44: =B41+B43 -> 0.50110073 | C44: =C41+C43 -> 0.5263341 | D44: =D41+D43 -> 0.55816538 | E44: =E41+E43 -> 0.54496362 | F44: =F41+F43 -> 0.50703256 | G44: =G41+G43 -> 0.47229346

Sheet Assumptions
A1: Snowflake Financial Model - Assumptions
A2: Enter your business assumptions below. The model will automatically calculate projections.
A4: Category | B4: Value | C4: Rationale
A5: Fiscal Year End | B5: 46023 | C5: Snowflake FY ends Jan 31
A6: Latest reported Quarter | B6: Q2FY 26 | C6: Reported August
A8: Product revenue ($m)
A9: FY 2026E (guidance midpoint,now tracking higher | B9: 4420
A10: RPO | B10: $6.9 B
A11: FY 2027E growth | B11: 0.26 | C11: Consesus- 26-27%. Slight Above mid-p0int = reasonable bull case
A12: FY 2028E growth | B12: 0.24 | C12: Fade 200 bps - standard for $5b revenue saas
A13: FY 2029E growth | B13: 0.22
A14: FY 2030E growth | B14: 0.19
A15: FY 2031E-FY2035E growth | B15: 16-12% | C15: Long term mature Saas Growth
A16: 1M+ Customer | B16: 0.14
A17: 1m+ Customer (post 2029E) | B17: 0.09
A18: Customer Growth | B18: 0.1
A19: Terminal Growth (beyond 2035) | B19: 0.04 | C19: Slightly Above GDP
A20: Net Revenue Retention (NRR) | B20: 0.03
A21: FY 2027E | B21: 1.26 | C21: Recent run-rate 125%+
A22: FY2028E | B22: 1.25
A23: FY 2029E+ | B23: 1.23 | C23: Long term fade-Data dog
A24: Gross Margins
A25: Product Gross Margin- FY 2026 | B25: 0.765 | C25: Company guidance 75% but historical-take 76.5%
A27: Product GM- improve 100 bps/yr | B27: 0.78 | C27: Optimization
A28: Large Customer Cohort (2026) | B28: 654 | C28: (>1M TTM Product Revenue)
A29: Operating EXPENSES (% of Revenue)
A30: R&D / Product Development | B30: 28%-24% | C30: Currently 28%- guiding down 100 bps
A31: S&M | B31: 42-35% | C31: Currently highest in saas-likely to improve
A32: G&A (General & Administrative) | B32: 11%-9% | C32: Efficient
A33: Stock Based Compensation | B33: 24-18% | C33: Will dilute as stock stabilizes
A34: Other
A35: Capex % revenue | B35: 0.015 | C35: Asset-light
A36: Amortization | B36: 1.5-0.5%
A37: Effective Tax Rate | B37: 0.25 | C37: US TAX
A38: Net Working Capital Days | B38: 0(-10days) | C38: Clean receivable
A39: FD Shares Outstanding(M) | B39: 335-375 by 2035
A40: Market Cap | B40: $86.6 B
A41: Enterprise Value | B41: $84 B | C41: (Net Cash)
A42: Current NTM multiple | B42: 19.0x
A43: Current market price | B43: $251
...

Sheet Revenue Model
A1: Revenue Model -Snowflake
A2: Desciption | B2: FY 2023 | C2: FY 2024 | D2: FY 2025 | E2: FY 2026 (E) | F2: FY 2027 E | G2: FY 2028 E | H2: FY 2029 E | I2: FY 2030 E | J2: FY 2031 E | T2: Month 16 | U2: Month 17 | V2: Month 18 | W2: Month 19 | X2: Month 20 | Y2: Month 21 | Z2: Month 22 | AA2: Month 23 | AB2: Month 24 | AC2: Month 25 | AD2: Month 26 | AE2: Month 27 | AF2: Month 28 | AG2: Month 29 | AH2: Month 30 | AI2: Month 31 | AJ2: Month 32 | AK2: Month 33 | AL2: Month 34 | AM2: Month 35 | AN2: Month 36
T3: =S6 -> 0 | U3: =T6 -> #REF! | V3: =U6 -> #REF! | W3: =V6 -> #REF! | X3: =W6 -> #REF! | Y3: =X6 -> #REF! | Z3: =Y6 -> #REF! | AA3: =Z6 -> #REF! | ... AN3: =AM6 -> #REF!
A4: Product Revenue | B4: 1939 | C4: 2667 | D4: 3462 | E4: =Assumptions!B9 -> 4420 | F4: =E4+(E4*F5) -> 5569.2 | G4: =F4+(F4*G5) -> 6905.808 | H4: =G4+(G4*H5) -> 8425.0858 | I4: =H4+(H4*I5) -> 10025.852 | J4: =I4+(I4*J5) -> 11629.988 | T4: =T3*3% -> 0 | U4: =U3*3% -> #REF! | V4: =V3*3% -> #REF! | W4: =W3*3% -> #REF! | X4: =X3*3% -> #REF! | Y4: =Y3*3% -> #REF! | Z4: =Z3*3% -> #REF! | AA4: =AA3*3% -> #REF! | ... AN4: =AN3*3% -> #REF!
A5: YoY Growth | B5: 0.7 | C5: 0.38 | D5: 0.3 | E5: =(E4-D4)/D4 -> 0.27671866 | F5: =Assumptions!B11 -> 0.26 | G5: =Assumptions!B12 -> 0.24 | H5: =Assumptions!B13 -> 0.22 | I5: =Assumptions!B14 -> 0.19 | J5: 0.16 | T5: =T3*2% -> 0 | U5: =U3*2% -> #REF! | V5: =V3*2% -> #REF! | W5: =W3*2% -> #REF! | X5: =X3*2% -> #REF! | Y5: =Y3*2% -> #REF! | Z5: =Z3*2% -> #REF! | AA5: =AA3*2% -> #REF! | ... AN5: =AN3*2% -> #REF!
A6: Revenue Bridge (NRR BUILD) | T6: =T3+T4-T5+#REF! -> #REF! | U6: =U3+U4-U5+#REF! -> #REF! | V6: =V3+V4-V5+#REF! -> #REF! | W6: =W3+W4-W5+#REF! -> #REF! | X6: =X3+X4-X5+#REF! -> #REF! | Y6: =Y3+Y4-Y5+#REF! -> #REF! | Z6: =Z3+Z4-Z5+#REF! -> #REF! | AA6: =AA3+AA4-AA5+#REF! -> #REF! | ... AP6: =AP3+AP4-AP5+#REF! -> #REF!
A7: Beginning Product Revenue | F7: =E4 -> 4420 | G7: =F11 -> 5567 | H7: =G11 -> 6905.808 | I7: =H11 -> 8425.0858 | J7: =I11 -> 10025.852
A8: * Net Revenue Retention (NRR) | B8: 1.58 | C8: 1.31 | D8: 1.26 | E8: 1.26 | F8: =Assumptions!B21 -> 1.26 | G8: =Assumptions!B22 -> 1.25 | H8: =Assumptions!B23 -> 1.23 | I8: =Assumptions!B23 -> 1.23 | J8: =Assumptions!B23 -> 1.23 | T8: =T4*Assumptions!$B$13 -> 0 | U8: =U4*Assumptions!$B$13 -> #REF! | V8: =V4*Assumptions!$B$13 -> #REF! | W8: =W4*Assumptions!$B$13 -> #REF! | X8: =X4*Assumptions!$B$13 -> #REF! | Y8: =Y4*Assumptions!$B$13 -> #REF! | Z8: =Z4*Assumptions!$B$13 -> #REF! | AA8: =AA4*Assumptions!$B$13 -> #REF! | ... AN8: =AN4*Assumptions!$B$13 -> #REF!
A9: Revenue from Existing Customer | E9: 4420 | F9: =(F7*F8) -> 5569.2 | G9: =(G7*G8) -> 6958.75 | H9: =(H7*H8) -> 8494.1438 | I9: =(I7*I8) -> 10362.855 | J9: =(J7*J8) -> 12331.798 | T9: =S11*Assumptions!$B$22 -> 0 | U9: =T11*Assumptions!$B$22 -> 0 | V9: =U11*Assumptions!$B$22 -> #REF! | W9: =V11*Assumptions!$B$22 -> #REF! | X9: =W11*Assumptions!$B$22 -> #REF! | Y9: =X11*Assumptions!$B$22 -> #REF! | Z9: =Y11*Assumptions!$B$22 -> #REF! | AA9: =Z11*Assumptions!$B$22 -> #REF! | ... AN9: =AM11*Assumptions!$B$22 -> #REF!
A10: New Customer Revenue | G10: =G4-G9 -> -52.942 | H10: =H4-H9 -> -69.05808 | I10: =I4-I9 -> -337.00343 | J10: =J4-J9 -> -701.80964 | T10: =T5*Assumptions!$B$13 -> 0 | U10: =U5*Assumptions!$B$13 -> #REF! | V10: =V5*Assumptions!$B$13 -> #REF! | W10: =W5*Assumptions!$B$13 -> #REF! | X10: =X5*Assumptions!$B$13 -> #REF! | Y10: =Y5*Assumptions!$B$13 -> #REF! | Z10: =Z5*Assumptions!$B$13 -> #REF! | AA10: =AA5*Assumptions!$B$13 -> #REF! | ... AN10: =AN5*Assumptions!$B$13 -> #REF!
A11: Total Product Revenue(check) | B11: 1939 | C11: 2667 | D11: 3462 | E11: 4420 | F11: 5567 | G11: =G9+G10 -> 6905.808 | H11: =H9+H10 -> 8425.0858 | I11: =I9+I10 -> 10025.852 | J11: =J9+J10 -> 11629.988 | T11: =T8+T9-T10 -> 0 | U11: =U8+U9-U10 -> #REF! | V11: =V8+V9-V10 -> #REF! | W11: =W8+W9-W10 -> #REF! | X11: =X8+X9-X10 -> #REF! | Y11: =Y8+Y9-Y10 -> #REF! | Z11: =Z8+Z9-Z10 -> #REF! | AA11: =AA8+AA9-AA10 -> #REF! | ... AN11: =AN8+AN9-AN10 -> #REF!
T12: =S12+T11 -> 0 | U12: =T12+U11 -> #REF! | V12: =U12+V11 -> #REF! | W12: =V12+W11 -> #REF! | X12: =W12+X11 -> #REF! | Y12: =X12+Y11 -> #REF! | Z12: =Y12+Z11 -> #REF! | AA12: =Z12+AA11 -> #REF! | ... AN12: =AM12+AN11 -> #REF!
T15: =T12 -> 0 | U15: =U12 -> #REF! | V15: =V12 -> #REF! | W15: =W12 -> #REF! | X15: =X12 -> #REF! | Y15: =Y12 -> #REF! | Z15: =Z12 -> #REF! | AA15: =AA12 -> #REF! | ... AN15: =AN12 -> #REF!
T16: =S16+T15 -> 0 | U16: =T16+U15 -> #REF! | V16: =U16+V15 -> #REF! | W16: =V16+W15 -> #REF! | X16: =W16+X15 -> #REF! | Y16: =X16+Y15 -> #REF! | Z16: =Y16+Z15 -> #REF! | AA16: =Z16+AA15 -> #REF! | ... AN16: =AM16+AN15 -> #REF!
T17: =T12*12 -> 0 | U17: =U12*12 -> #REF! | V17: =V12*12 -> #REF! | W17: =W12*12 -> #REF! | X17: =X12*12 -> #REF! | Y17: =Y12*12 -> #REF! | Z17: =Z12*12 -> #REF! | AA17: =AA12*12 -> #REF! | ... AN17: =AN12*12 -> #REF!

Sheet Profit and loss statement
A1: Profit & Loss
A2: Description | B2: ='Revenue Model'!B2 -> FY 2023 | C2: ='Revenue Model'!C2 -> FY 2024 | D2: ='Revenue Model'!D2 -> FY 2025 | E2: ='Revenue Model'!E2 -> FY 2026 (E) | F2: ='Revenue Model'!F2 -> FY 2027 E | G2: ='Revenue Model'!G2 -> FY 2028 E | H2: ='Revenue Model'!H2 -> FY 2029 E | I2: ='Revenue Model'!I2 -> FY 2030 E | J2: ='Revenue Model'!J2 -> FY 2031 E
A3: Product Revenue | B3: ='Revenue Model'!B4 -> 1939 | C3: ='Revenue Model'!C4 -> 2667 | D3: ='Revenue Model'!D4 -> 3462 | E3: ='Revenue Model'!E4 -> 4420 | F3: ='Revenue Model'!F4 -> 5569.2 | G3: ='Revenue Model'!G4 -> 6905.808 | H3: ='Revenue Model'!H4 -> 8425.0858 | I3: ='Revenue Model'!I4 -> 10025.852 | J3: ='Revenue Model'!J4 -> 11629.988
A4: Professional service and other Revenue | B4: 128 | C4: 139 | D4: 164 | E4: =(E3*5%) -> 221 | F4: =(F3*5%) -> 278.46 | G4: =(G3*5%) -> 345.2904 | H4: =(H3*5%) -> 421.25429 | I4: =(I3*5%) -> 501.2926 | J4: =(J3*5%) -> 581.49942
A5: Total Revenue | B5: 2066 | C5: 2806 | D5: 3626 | E5: =E3+E4 -> 4641 | F5: =F3+F4 -> 5847.66 | G5: =G3+G4 -> 7251.0984 | H5: =H3+H4 -> 8846.34 | I5: =I3+I4 -> 10527.145 | J5: =J3+J4 -> 12211.488
A7: Cost OF Revenue-Product | B7: 548 | C7: 701 | D7: 992 | E7: -1061 | F7: ='Profit and loss statement'!F5*(1-Assumptions!$B$27) -> 1286.4852 | G7: ='Profit and loss statement'!G5*(1-Assumptions!$B$27) -> 1595.2416 | H7: ='Profit and loss statement'!H5*(1-Assumptions!$B$27) -> 1946.1948 | I7: ='Profit and loss statement'!I5*(1-Assumptions!$B$27) -> 2315.9718 | J7: ='Profit and loss statement'!J5*(1-Assumptions!$B$27) -> 2686.5273
A8: Cost OF Revenue-Services | B8: 170 | C8: 197 | D8: 223 | E8: -180 | F8: =F3*3% -> 167.076 | G8: =G3*2.5% -> 172.6452 | H8: =H3*3% -> 252.75257 | I8: =I3*2% -> 200.51704 | J8: =J3*2% -> 232.59977
A9: Total cost of revenue | B9: =B7+B8 -> 718 | C9: =C7+C8 -> 898 | D9: =D7+D8 -> 1215 | E9: -1241 | F9: =F7+F8 -> 1453.5612 | G9: =G7+G8 -> 1767.8868 | H9: =H7+H8 -> 2198.9474 | I9: =I7+I8 -> 2516.4889 | J9: =J7+J8 -> 2919.1271
A10: Gross Profit | B10: =B5-B7-B8 -> 1348 | C10: =C5-C7-C8 -> 1908 | D10: =D5-D7-D8 -> 2411 | E10: =E5+E9 -> 3400 | F10: =F5-F9 -> 4394.0988 | G10: =G5-G9 -> 5483.2116 | H10: =H5-H9 -> 6647.3927 | I10: =I5-I9 -> 8010.6558 | J10: =J5-J9 -> 9292.3607
A11: Gross margin % | B11: =B10/B5 -> 0.65246854 | C11: =C10/C5 -> 0.67997149 | D11: =D10/D5 -> 0.66492002 | E11: =E10/E5 -> 0.73260073 | F11: =F10/F5 -> 0.75142857 | G11: =G10/G5 -> 0.75619048 | H11: =H10/H5 -> 0.75142857 | I11: =I10/I5 -> 0.76095238 | J11: =J10/J5 -> 0.76095238
A13: Operating Expenses:
A14: Research & Development | B14: 788 | C14: 1281 | D14: 1772 | E14: =E5*E15 -> 1624.35 | F14: =F5*F15 -> 1929.7278 | G14: =G5*G15 -> 2102.8185 | H14: =H5*H15 -> 2388.5118 | I14: =I5*I15 -> 2631.7862 | J14: =J5*J15 -> 2991.8145
A15: % of Revenue | B15: =B14/B5 -> 0.38141336 | C15: =C14/C5 -> 0.45652174 | D15: =D14/D5 -> 0.48869277 | E15: 0.35 | F15: 0.33 | G15: 0.29 | H15: 0.27 | I15: 0.25 | J15: 0.245
A16: Sales & Marketing | B16: 1112 | C16: 1352 | D16: 1639 | E16: =E5*E17 -> 1995.63 | F16: =F5*F17 -> 2456.0172 | G16: =G5*G17 -> 2900.4394 | H16: =H5*H17 -> 3450.0726 | I16: =I5*I17 -> 3895.0435 | J16: =J5*J17 -> 4274.0207
A17: % of Revenue | B17: =B16/B5 -> 0.53823814 | C17: =C16/C5 -> 0.48182466 | D17: =D16/D5 -> 0.45201324 | E17: 0.43 | F17: 0.42 | G17: 0.4 | H17: 0.39 | I17: 0.37 | J17: 0.35 | L17: ]
A18: G&A | B18: 285 | C18: 363 | D18: 445 | E18: =E5*E19 -> 510.51 | F18: =F5*F19 -> 584.766 | G18: =G5*G19 -> 725.10984 | H18: =H5*H19 -> 840.4023 | I18: =I5*I19 -> 947.44302 | J18: =J5*J19 -> 1099.0339
A19: % of Revenue | B19: =B18/B5 -> 0.13794773 | C19: =C18/C5 -> 0.12936565 | D19: =D18/D5 -> 0.12272477 | E19: 0.11 | F19: 0.1 | G19: 0.1 | H19: 0.095 | I19: 0.09 | J19: 0.09
A20: Total Operating Expenses | B20: =B14+B16+B18 -> 2185 | C20: =C14+C16+C18 -> 2996 | D20: =D14+D16+D18 -> 3856 | E20: =E14+E16+E18 -> 4130.49 | F20: =F14+F16+F18 -> 4970.511 | G20: =G14+G16+G18 -> 5728.3677 | H20: =H14+H16+H18 -> 6678.9867 | I20: =I14+I16+I18 -> 7474.2727 | J20: =J14+J16+J18 -> 8364.8691
A21: GAAP Op income | B21: -842 | C21: -1095 | D21: -1456 | E21: =E10-E20 -> -730.49 | F21: =F10-F20 -> -576.4122 | G21: =G10-G20 -> -245.15618 | H21: =H10-H20 -> -31.594072 | I21: =I10-I20 -> 536.38308 | J21: =J10-J20 -> 927.49157
A22: ADD:Share based compensation | B22: 1080 | C22: 1300 | E22: =E5*E23 -> 1299.48 | F22: =F5*F23 -> 1637.3448 | G22: =G5*G23 -> 1957.7966 | H22: =H5*H23 -> 2211.585 | I22: =I5*I23 -> 2105.4289 | J22: =J5*J23 -> 2198.0678
A23: %of Revenue | E23: 0.28 | F23: 0.28 | G23: 0.27 | H23: 0.25 | I23: 0.2 | J23: 0.18
A24: ADD:Amortization | B24: 0 | C24: 29 | D24: 0 | E24: =E5*E25 -> 69.615 | F24: =F5*F25 -> 70.17192 | G24: =G5*G25 -> 72.510984 | H24: =H5*H25 -> 88.4634 | I24: =I5*I25 -> 78.953585 | J24: =J5*J25 -> 61.057439
A25: % of Revenue | E25: 0.015 | F25: 0.012 | G25: 0.01 | H25: 0.01 | I25: 0.0075 | J25: 0.005
A26: Non-Gaap Operating Income | C26: $39 | D26: 100 | E26: =E21+E22+E24 -> 638.605 | F26: =F21+F22+F24 -> 1131.1045 | G26: =G21+G22+G24 -> 1785.1514 | H26: =H21+H22+H24 -> 2268.4543 | I26: =I21+I22+I24 -> 2720.7656 | J26: =J21+J22+J24 -> 3186.6168
A27: Non-Gaap Operating Margin | C27: 3-5% | D27: 0.03 | E27: =E26/E5 -> 0.13760073 | F27: =F26/F5 -> 0.19342857 | G27: =G26/G5 -> 0.24619048 | H27: =H26/H5 -> 0.25642857 | I27: =I26/I5 -> 0.25845238 | J27: =J26/J5 -> 0.26095238

Sheet Working Capital
A1: KEY ASSUMPTIONS
A3: Metric | B3: Project Rationale | C3: FY 2026 Assumptions
A4: Days Sales Outstanding (DSO) | B4: Enterprise Saas usually has clean collection | C4: 40 Days
A5: Days Payable Outstanding | B5: Strong Bargaining power with cloud vendors | C5: 50 Days
A6: Deferred Revenue Ratio | B6: Driven by large upfront RPO | C6: 45% of Product revenue
A9: Schedule Calculation
A10: Metric (in millions) | B10: ='Revenue Model'!D2 -> FY 2025 | C10: ='Revenue Model'!E2 -> FY 2026 (E) | D10: ='Revenue Model'!F2 -> FY 2027 E | E10: ='Revenue Model'!G2 -> FY 2028 E | F10: ='Revenue Model'!H2 -> FY 2029 E | G10: ='Revenue Model'!I2 -> FY 2030 E | H10: ='Revenue Model'!J2 -> FY 2031 E
A12: Total Revenue | B12: ='Profit and loss statement'!D5 -> 3626 | C12: ='Profit and loss statement'!E5 -> 4641 | D12: ='Profit and loss statement'!F5 -> 5847.66 | E12: ='Profit and loss statement'!G5 -> 7251.0984 | F12: ='Profit and loss statement'!H5 -> 8846.34 | G12: ='Profit and loss statement'!I5 -> 10527.145 | H12: ='Profit and loss statement'!J5 -> 12211.488
A13: COGS | B13: ='Profit and loss statement'!D9 -> 1215 | C13: ='Profit and loss statement'!E9*-1 -> 1241 | D13: ='Profit and loss statement'!F9 -> 1453.5612 | E13: ='Profit and loss statement'!G9 -> 1767.8868 | F13: ='Profit and loss statement'!H9 -> 2198.9474 | G13: ='Profit and loss statement'!I9 -> 2516.4889 | H13: ='Profit and loss statement'!J9 -> 2919.1271
A15: Account Receivable (A/R)-Cash Outflow | B15: =B12/365*40 -> 397.36986 | C15: =(C12/365)*40 -> 508.60274 | D15: =(D12/365)*40 -> 640.83945 | E15: =(E12/365)*40 -> 794.64092 | F15: =(F12/365)*40 -> 969.46192 | G15: =(G12/365)*40 -> 1153.6597 | H15: =(H12/365)*40 -> 1338.2452
A16: Change in AR | C16: =C15-B15 -> 111.23288 | D16: =D15-C15 -> 132.23671 | E16: =E15-D15 -> 153.80147 | F16: =F15-E15 -> 174.821 | G16: =G15-F15 -> 184.19777 | H16: =H15-G15 -> 184.58555
A18: Deferred Revenue
A19: DR Balance | B19: 1558 | C19: =C12*45% -> 2088.45 | D19: =D12*45% -> 2631.447 | E19: =E12*45% -> 3262.9943 | F19: =F12*45% -> 3980.853 | G19: =G12*45% -> 4737.2151 | H19: =H12*45% -> 5495.1695
A20: Change in DR | C20: =C19-B19 -> 530.45 | D20: =D19-C19 -> 542.997 | E20: =E19-D19 -> 631.54728 | F20: =F19-E19 -> 717.85874 | G20: =G19-F19 -> 756.36207 | H20: =H19-G19 -> 757.95442
A22: Account Payable
A23: AP Balance | B23: =(B13/365)*50 -> 166.43836 | C23: =(C13/365)*50 -> 170 | D23: =(D13/365)*50 -> 199.11797 | E23: =(E13/365)*50 -> 242.17628 | F23: =(F13/365)*50 -> 301.22567 | G23: =(G13/365)*50 -> 344.7245 | H23: =(H13/365)*50 -> 399.88042
A24: Change in Payable | C24: =C23-B23 -> 3.5616438 | D24: =D23-C23 -> 29.117973 | E24: =E23-D23 -> 43.058308 | F24: =F23-E23 -> 59.049388 | G24: =G23-F23 -> 43.498833 | H24: =H23-G23 -> 55.15592
A26: Change in NWC | C26: =-C16+C20+C24 -> 422.77877 | D26: =-D16+D20+D24 -> 439.87826 | E26: =-E16+E20+E24 -> 520.80412 | F26: =-F16+F20+F24 -> 602.08713 | G26: =-G16+G20+G24 -> 615.66314 | H26: =-H16+H20+H24 -> 628.52479
A27: (-AR+DR+AP)

Sheet DCF
A1: DCF & Sensitive Analysis
Z2: Month 25 | AA2: Month 26 | AB2: Month 27 | AC2: Month 28 | AD2: Month 29 | AE2: Month 30 | AF2: Month 31 | AG2: Month 32 | AH2: Month 33 | AI2: Month 34 | AJ2: Month 35 | AK2: Month 36
A3: CASH FLOW TAB
Z4: ='Revenue Model'!AC15 -> #REF! | AA4: ='Revenue Model'!AD15 -> #REF! | AB4: ='Revenue Model'!AE15 -> #REF! | AC4: ='Revenue Model'!AF15 -> #REF! | AD4: ='Revenue Model'!AG15 -> #REF! | AE4: ='Revenue Model'!AH15 -> #REF! | AF4: ='Revenue Model'!AI15 -> #REF! | AG4: ='Revenue Model'!AJ15 -> #REF! | ... AK4: ='Revenue Model'!AN15 -> #REF!
A5: Cash flow from operation | B5: ='Revenue Model'!E2 -> FY 2026 (E) | C5: ='Revenue Model'!F2 -> FY 2027 E | D5: ='Revenue Model'!G2 -> FY 2028 E | E5: ='Revenue Model'!H2 -> FY 2029 E | F5: ='Revenue Model'!I2 -> FY 2030 E | G5: ='Revenue Model'!J2 -> FY 2031 E | Z5: =IF(25=Assumptions!$B$45,Assumptions!$B$44,0) -> 0 | AA5: =IF(26=Assumptions!$B$45,Assumptions!$B$44,0) -> 0 | AB5: =IF(27=Assumptions!$B$45,Assumptions!$B$44,0) -> 0 | AC5: =IF(28=Assumptions!$B$45,Assumptions!$B$44,0) -> 0 | AD5: =IF(29=Assumptions!$B$45,Assumptions!$B$44,0) -> 0 | AE5: =IF(30=Assumptions!$B$45,Assumptions!$B$44,0) -> 0 | AF5: =IF(31=Assumptions!$B$45,Assumptions!$B$44,0) -> 0 | AG5: =IF(32=Assumptions!$B$45,Assumptions!$B$44,0) -> 0 | AH5: =IF(33=Assumptions!$B$45,Assumptions!$B$44,0) -> 0 | AI5: =IF(34=Assumptions!$B$45,Assumptions!$B$44,0) -> 0 | AJ5: =IF(35=Assumptions!$B$45,Assumptions!$B$44,0) -> 0 | AK5: =IF(36=Assumptions!$B$45,Assumptions!$B$44,0) -> 0
Z6: =Z4+Z5 -> #REF! | AA6: =AA4+AA5 -> #REF! | AB6: =AB4+AB5 -> #REF! | AC6: =AC4+AC5 -> #REF! | AD6: =AD4+AD5 -> #REF! | AE6: =AE4+AE5 -> #REF! | AF6: =AF4+AF5 -> #REF! | AG6: =AG4+AG5 -> #REF! | ... AK6: =AK4+AK5 -> #REF!
A7: GAAP operating income | B7: ='Profit and loss statement'!E21 -> -730.49 | C7: ='Profit and loss statement'!F21 -> -576.4122 | D7: ='Profit and loss statement'!G21 -> -245.15618 | E7: ='Profit and loss statement'!H21 -> -31.594072 | F7: ='Profit and loss statement'!I21 -> 536.38308 | G7: ='Profit and loss statement'!J21 -> 927.49157
A8: ADD:Share based compensation | B8: ='Profit and loss statement'!E22 -> 1299.48 | C8: ='Profit and loss statement'!F22 -> 1637.3448 | D8: ='Profit and loss statement'!G22 -> 1957.7966 | E8: ='Profit and loss statement'!H22 -> 2211.585 | F8: ='Profit and loss statement'!I22 -> 2105.4289 | G8: ='Profit and loss statement'!J22 -> 2198.0678
A9: Add:Amortization | B9: ='Profit and loss statement'!E24 -> 69.615 | C9: ='Profit and loss statement'!F24 -> 70.17192 | D9: ='Profit and loss statement'!G24 -> 72.510984 | E9: ='Profit and loss statement'!H24 -> 88.4634 | F9: ='Profit and loss statement'!I24 -> 78.953585 | G9: ='Profit and loss statement'!J24 -> 61.057439 | Z9: ='Profit and loss statement'!H16 -> 3450.0726 | AA9: ='Profit and loss statement'!I16 -> 3895.0435 | AB9: ='Profit and loss statement'!J16 -> 4274.0207 | AC9: ='Profit and loss statement'!K16 -> 0 | AD9: ='Profit and loss statement'!L16 -> 0 | AE9: ='Profit and loss statement'!M16 -> 0 | AF9: ='Profit and loss statement'!N16 -> 0 | AG9: ='Profit and loss statement'!O16 -> 0 | ... AK9: ='Profit and loss statement'!S16 -> 0
A10: Changes in NWC | B10: ='Working Capital'!C26 -> 422.77877 | C10: ='Working Capital'!D26 -> 439.87826 | D10: ='Working Capital'!E26 -> 520.80412 | E10: ='Working Capital'!F26 -> 602.08713 | F10: ='Working Capital'!G26 -> 615.66314 | G10: ='Working Capital'!H26 -> 628.52479 | Z10: =Z9 -> 3450.0726 | AA10: =AA9 -> 3895.0435 | AB10: =AB9 -> 4274.0207 | AC10: =AC9 -> 0 | AD10: =AD9 -> 0 | AE10: =AE9 -> 0 | AF10: =AF9 -> 0 | AG10: =AG9 -> 0 | ... AK10: =AK9 -> 0
A12: CFO | B12: =B7+B8+B9+B10 -> 1061.3838 | C12: =C7+C8+C9+C10 -> 1570.9828 | D12: =D7+D8+D9+D10 -> 2305.9555 | E12: =E7+E8+E9+E10 -> 2870.5415 | F12: =F7+F8+F9+F10 -> 3336.4287 | G12: =G7+G8+G9+G10 -> 3815.1416
Z13: =Z6-Z10 -> #REF! | AA13: =AA6-AA10 -> #REF! | AB13: =AB6-AB10 -> #REF! | AC13: =AC6-AC10 -> #REF! | AD13: =AD6-AD10 -> #REF! | AE13: =AE6-AE10 -> #REF! | AF13: =AF6-AF10 -> #REF! | AG13: =AG6-AG10 -> #REF! | ... AK13: =AK6-AK10 -> #REF!
A14: Cash Flow from investing | Z14: =Y14+Z13 -> #REF! | AA14: =Z14+AA13 -> #REF! | AB14: =AA14+AB13 -> #REF! | AC14: =AB14+AC13 -> #REF! | AD14: =AC14+AD13 -> #REF! | AE14: =AD14+AE13 -> #REF! | AF14: =AE14+AF13 -> #REF! | AG14: =AF14+AG13 -> #REF! | ... AK14: =AJ14+AK13 -> #REF!
A15: Less:Capex | B15: ='Profit and loss statement'!E5*Assumptions!$B$35 -> 69.615 | C15: ='Profit and loss statement'!F5*Assumptions!$B$35 -> 87.7149 | D15: ='Profit and loss statement'!G5*Assumptions!$B$35 -> 108.76648 | E15: ='Profit and loss statement'!H5*Assumptions!$B$35 -> 132.6951 | F15: ='Profit and loss statement'!I5*Assumptions!$B$35 -> 157.90717 | G15: ='Profit and loss statement'!J5*Assumptions!$B$35 -> 183.17232
A16: FCF | B16: =B12-B15 -> 991.76877 | C16: =C12-C15 -> 1483.2679 | D16: =D12-D15 -> 2197.189 | E16: =E12-E15 -> 2737.8464 | F16: =F12-F15 -> 3178.5216 | G16: =G12-G15 -> 3631.9693
C17: =(C16-B16)/B16 -> 0.49557833 | D17: =(D16-C16)/C16 -> 0.48131638 | E17: =(E16-D16)/D16 -> 0.24606775 | F17: =(F16-E16)/E16 -> 0.16095688 | G17: =(G16-F16)/F16 -> 0.14265994
A18: Terminal value | B18: 0 | C18: 0 | D18: 0 | E18: 0 | F18: 0 | G18: =G16*(1+B24)/(B23-B24) -> 83938.846 | Z18: =IF(Z13>0,999,IF(Z13<0,Z14/ABS(Z13),999)) -> #REF! | AA18: =IF(AA13>0,999,IF(AA13<0,AA14/ABS(AA13),999)) -> #REF! | AB18: =IF(AB13>0,999,IF(AB13<0,AB14/ABS(AB13),999)) -> #REF! | AC18: =IF(AC13>0,999,IF(AC13<0,AC14/ABS(AC13),999)) -> #REF! | AD18: =IF(AD13>0,999,IF(AD13<0,AD14/ABS(AD13),999)) -> #REF! | AE18: =IF(AE13>0,999,IF(AE13<0,AE14/ABS(AE13),999)) -> #REF! | AF18: =IF(AF13>0,999,IF(AF13<0,AF14/ABS(AF13),999)) -> #REF! | AG18: =IF(AG13>0,999,IF(AG13<0,AG14/ABS(AG13),999)) -> #REF! | ... AK18: =IF(AK13>0,999,IF(AK13<0,AK14/ABS(AK13),999)) -> #REF!
Z19: =IF(Z13>=0,"Profitable","Burning") -> #REF! | AA19: =IF(AA13>=0,"Profitable","Burning") -> #REF! | AB19: =IF(AB13>=0,"Profitable","Burning") -> #REF! | AC19: =IF(AC13>=0,"Profitable","Burning") -> #REF! | AD19: =IF(AD13>=0,"Profitable","Burning") -> #REF! | AE19: =IF(AE13>=0,"Profitable","Burning") -> #REF! | AF19: =IF(AF13>=0,"Profitable","Burning") -> #REF! | AG19: =IF(AG13>=0,"Profitable","Burning") -> #REF! | ... AK19: =IF(AK13>=0,"Profitable","Burning") -> #REF!
A22: Valuation
A23: WACC | B23: 0.085 | C23: (Investing.com) | I23: =B36 -> 189.69481 | J23: 0.07 | K23: 0.075 | L23: 0.08 | M23: 0.085 | N23: 0.095
A24: Terminal Value | B24: 0.04 | C24: (US GDP+ inflation) | I24: 0.025 | J24: 202.40102 | K24: 181.26706 | L24: 164.00201 | M24: 149.63802 | N24: 127.1245
I25: 0.035 | J25: 251.48027 | K25: 219.02646 | L25: 193.81485 | M25: 173.67209 | N25: 143.52199
I26: 0.04 | J26: 288.28971 | K26: 245.99745 | L26: 214.31118 | M26: 189.69481 | N26: 153.95676
A27: Perpetuity Growth Method | I27: 0.05 | J27: 417.12274 | K27: 332.30464 | L27: 275.80017 | M27: 235.474 | N27: 181.78281
I28: 0.06 | J28: 803.62183 | K28: 533.68809 | L28: 398.77814 | M28: 317.87654 | N28: 225.50946
A29: NPV of Explicit value | B29: =NPV(B23,B16:G16) -> 10209.858
A30: Npv of terminal value | B30: =NPV(B23,B18:G18) -> 51449.903
A31: Enterprise value | B31: =B29+B30 -> 61659.761
A32: Add:Cash | B32: 4157
A33: Less:Debt | B33: 2269
A34: Equity Value | B34: =B31+B32-B33 -> 63547.761
A35: Shares Outstanding(M) | B35: 335
A36: Intrinsic value | B36: =B34/B35 -> 189.69481

Sheet Unit Economics
A1: Unit Economics & Key Metrics
A2: Metric | B2: ='Profit and loss statement'!C2 -> FY 2024 | C2: ='Profit and loss statement'!D2 -> FY 2025 | D2: ='Profit and loss statement'!E2 -> FY 2026 (E) | E2: ='Profit and loss statement'!F2 -> FY 2027 E | F2: ='Profit and loss statement'!G2 -> FY 2028 E | G2: ='Profit and loss statement'!H2 -> FY 2029 E | H2: ='Profit and loss statement'!I2 -> FY 2030 E | I2: ='Profit and loss statement'!J2 -> FY 2031 E
A3: Revenue(M) | B3: ='Profit and loss statement'!C3 -> 2667 | C3: ='Profit and loss statement'!D3 -> 3462 | D3: ='Profit and loss statement'!E3 -> 4420 | E3: ='Profit and loss statement'!F3 -> 5569.2 | F3: ='Profit and loss statement'!G3 -> 6905.808 | G3: ='Profit and loss statement'!H3 -> 8425.0858 | H3: ='Profit and loss statement'!I3 -> 10025.852 | I3: ='Profit and loss statement'!J3 -> 11629.988
A4: S&M Expense(M) | B4: ='Profit and loss statement'!C16 -> 1352 | C4: ='Profit and loss statement'!D16 -> 1639 | D4: ='Profit and loss statement'!E16 -> 1995.63 | E4: ='Profit and loss statement'!F16 -> 2456.0172 | F4: ='Profit and loss statement'!G16 -> 2900.4394 | G4: ='Profit and loss statement'!H16 -> 3450.0726 | H4: ='Profit and loss statement'!I16 -> 3895.0435 | I4: ='Profit and loss statement'!J16 -> 4274.0207
A5: Total Customer | B5: 9437 | C5: 11000 | D5: 13180 | E5: =D5+(D5*Assumptions!$B$18) -> 14498 | F5: =E5+(E5*Assumptions!$B$18) -> 15947.8 | G5: =F5+(F5*Assumptions!$B$18) -> 17542.58 | H5: =G5+(G5*Assumptions!$B$18) -> 19296.838 | I5: =H5+(H5*Assumptions!$B$18) -> 21226.522
A6: New Customer | B6: 1599 | C6: 1722 | D6: =(D5*Assumptions!$B$18)+('Unit Economics'!D5*'Unit Economics'!D12) -> 1977 | E6: =(E5*Assumptions!$B$18)+('Unit Economics'!E5*'Unit Economics'!E12) -> 2174.7 | F6: =(F5*Assumptions!$B$18)+('Unit Economics'!F5*'Unit Economics'!F12) -> 2392.17 | G6: =(G5*Assumptions!$B$18)+('Unit Economics'!G5*'Unit Economics'!G12) -> 2631.387 | H6: =(H5*Assumptions!$B$18)+('Unit Economics'!H5*'Unit Economics'!H12) -> 2894.5257 | I6: =(I5*Assumptions!$B$18)+('Unit Economics'!I5*'Unit Economics'!I12) -> 3183.9783
A7: 1Million + Customer | B7: 461 | C7: 510 | D7: 688 | E7: =D7+(D7*Assumptions!$B$16) -> 784.32 | F7: =E7+(E7*Assumptions!$B$16) -> 894.1248 | G7: =F7+(F7*Assumptions!$B$16) -> 1019.3023 | H7: =G7+(G7*Assumptions!$B$17) -> 1111.0395 | I7: =H7+(H7*Assumptions!$B$17) -> 1211.033
A8: CUSTOMER METRICS
A9: Average Revenue Per Account (ARPA)(M) | B9: =B3/B5 -> 0.282611 | C9: =C3/C5 -> 0.31472727 | D9: =(D3/D5) -> 0.3353566 | E9: =(E3/E5) -> 0.38413574 | F9: =(F3/F5) -> 0.43302575 | G9: =(G3/G5) -> 0.48026492 | H9: =(H3/H5) -> 0.51955932 | I9: =(I3/I5) -> 0.54789892
A10: Customer Lifetime (months) | B10: =1/B12*12 -> 240 | C10: =1/C12*12 -> 240 | D10: =1/D12*12 -> 240 | E10: =1/E12*12 -> 240 | F10: =1/F12*12 -> 240 | G10: =1/G12*12 -> 240 | H10: =1/H12*12 -> 240 | I10: =1/I12*12 -> 240
A11: Customer Lifetime Value (LTV)(M) | B11: =(B9*B19)/B12 -> 3.8433484 | C11: =(C9*C19)/C12 -> 4.1853693 | D11: =(D9*D19)/D12 -> 4.9136498 | E11: =(E9*E19)/E12 -> 5.7730114 | F11: =(F9*F19)/F12 -> 6.5489989 | G11: =(G9*G19)/G12 -> 7.2176956 | H11: =(H9*H19)/H12 -> 7.9071981 | I11: =(I9*I19)/I12 -> 8.3384998
A12: Churn Rate | B12: 0.05 | C12: 0.05 | D12: 0.05 | E12: 0.05 | F12: 0.05 | G12: 0.05 | H12: 0.05 | I12: 0.05
A13: ACQUISITION METRICS
A14: Customer Acquisition Cost (CAC)(M) | B14: =B4/B6 -> 0.84552846 | C14: =C4/C6 -> 0.95180023 | D14: =D4/D6 -> 1.0094234 | E14: =E4/E6 -> 1.1293591 | F14: =F4/F6 -> 1.2124721 | G14: =G4/G6 -> 1.3111232 | H14: =H4/H6 -> 1.3456586 | I14: =I4/I6 -> 1.3423524
A15: LTV / CAC Ratio | B15: =B11/B14 -> 4.5454986 | C15: =C11/C14 -> 4.3973191 | D15: =D11/D14 -> 4.867779 | E15: =E11/E14 -> 5.111759 | F15: =F11/F14 -> 5.4013605 | G15: =G11/G14 -> 5.5049712 | H15: =H11/H14 -> 5.8760802 | I15: =I11/I14 -> 6.2118562
A16: CAC Payback Period (months) | B16: =B14/((B9*B19)/12) -> 52.799488 | C16: =C14/((C9*C19)/12) -> 54.57871 | D16: =D14/((D9*D19)/12) -> 49.3038 | E16: =E14/((E9*E19)/12) -> 46.95057 | F16: =F14/((F9*F19)/12) -> 44.433249 | G16: =G14/((G9*G19)/12) -> 43.596958 | H16: =H14/((H9*H19)/12) -> 40.843554 | I16: =I14/((I9*I19)/12) -> 38.635795
A18: EFFICIENCY METRICS
A19: Gross Margin % | B19: ='Profit and loss statement'!C11 -> 0.67997149 | C19: ='Profit and loss statement'!D11 -> 0.66492002 | D19: ='Profit and loss statement'!E11 -> 0.73260073 | E19: ='Profit and loss statement'!F11 -> 0.75142857 | F19: ='Profit and loss statement'!G11 -> 0.75619048 | G19: ='Profit and loss statement'!H11 -> 0.75142857 | H19: ='Profit and loss statement'!I11 -> 0.76095238 | I19: ='Profit and loss statement'!J11 -> 0.76095238
A21: Net Revenue Retention | B21: ='Revenue Model'!C8 -> 1.31 | C21: ='Revenue Model'!D8 -> 1.26 | D21: ='Revenue Model'!E8 -> 1.26 | E21: ='Revenue Model'!F8 -> 1.26 | F21: ='Revenue Model'!G8 -> 1.25 | G21: ='Revenue Model'!H8 -> 1.23 | H21: ='Revenue Model'!I8 -> 1.23 | I21: ='Revenue Model'!J8 -> 1.23
A23: MAGIC NUMBER
A24: Sales Efficiency (Magic Number) | C24: =(C3-B3)/B4 -> 0.58801775 | D24: =(D3-C3)/C4 -> 0.58450275 | E24: =(E3-D3)/D4 -> 0.57585825 | F24: =(F3-E3)/E4 -> 0.54421769 | G24: =(G3-F3)/F4 -> 0.52380952 | H24: =(H3-G3)/G4 -> 0.46398046 | I24: =(I3-H3)/H4 -> 0.41184041
